<?xml version="1.0"?>
<robot name="example">

<!-- LADO IZQUIERDO  -->

<!-- MOTOR 1 -->
  <link name="link11">
    <inertial>
      <mass value="1"/>
      <inertia ixx="1" iyy="1" izz="1" ixy="0" ixz="0" iyz="0"/>
    </inertial>
  </link>
  
  <link name="link12">
    <inertial>
      <mass value="1"/>
      <inertia ixx="1" iyy="1" izz="1" ixy="0" ixz="0" iyz="0"/>
    </inertial>
  </link>
  
  <joint name="test_joint" type="revolute">
    <parent link="link11"/>
    <child link="link12"/>
    <limit lower="-10000.0" upper="10000.0" effort="3.0" velocity="10.0">
    ## effort in  (N-m )
    ## velocity in rad/s
    </limit>
  </joint>

  <transmission name="test_joint_trans1">
    <type>transmission_interface/SimpleTransmission</type>
    <joint name="test_joint1">
      <!--hardwareInterface>hardware_interface/VelocityJointInterface</hardwareInterface-->
      <hardwareInterface>hardware_interface/PositionJointInterface</hardwareInterface>
    </joint>
    <actuator name="epos_hardware/front_left_drive_actuator">
      <!-- <mechanicalReduction>330.625</mechanicalReduction> --> <!-- 529/16 -->
      <mechanicalReduction>333.0</mechanicalReduction>
    </actuator>
  </transmission>


<!-- MOTOR 3 -->
 <link name="link31">
    <inertial>
      <mass value="1"/>
      <inertia ixx="1" iyy="1" izz="1" ixy="0" ixz="0" iyz="0"/>
    </inertial>
  </link>

  <link name="link32">
    <inertial>
      <mass value="1"/>
      <inertia ixx="1" iyy="1" izz="1" ixy="0" ixz="0" iyz="0"/>
    </inertial>
  </link>

  <joint name="test_joint3" type="revolute">
    <parent link="link31"/>
    <child link="link32"/>
    <limit lower="-10000.0" upper="10000.0" effort="3.0" velocity="10.0">
    ## effort in  (N-m )
    ## velocity in rad/s
    </limit>
  </joint>

  <transmission name="test_joint_trans3">
    <type>transmission_interface/SimpleTransmission</type>
    <joint name="test_joint3">
      <!-- <hardwareInterface>hardware_interface/VelocityJointInterface</hardwareInterface> -->
      <hardwareInterface>hardware_interface/PositionJointInterface</hardwareInterface>
    </joint>
    <actuator name="epos_hardware/middle_left_drive_actuator">
      <!-- <mechanicalReduction>330.625</mechanicalReduction> --> <!-- 529/16 -->
      <mechanicalReduction>333.0</mechanicalReduction>
    </actuator>
  </transmission>


<!-- MOTOR  5-->
 <link name="link51">
    <inertial>
      <mass value="1"/>
      <inertia ixx="1" iyy="1" izz="1" ixy="0" ixz="0" iyz="0"/>
    </inertial>
  </link>

  <link name="link52">
    <inertial>
      <mass value="1"/>
      <inertia ixx="1" iyy="1" izz="1" ixy="0" ixz="0" iyz="0"/>
    </inertial>
  </link>

  <joint name="test_joint5" type="revolute">
    <parent link="link51"/>
    <child link="link52"/>
    <limit lower="-10000.0" upper="10000.0" effort="3.0" velocity="10.0">
    ## effort in  (N-m )
    ## velocity in rad/s
    </limit>
  </joint>

  <transmission name="test_joint_trans5">
    <type>transmission_interface/SimpleTransmission</type>
    <joint name="test_joint5">
      <!-- <hardwareInterface>hardware_interface/VelocityJointInterface</hardwareInterface> -->
      <hardwareInterface>hardware_interface/PositionJointInterface</hardwareInterface>
    </joint>
    <actuator name="epos_hardware/back_left_drive_actuator">
      <!-- <mechanicalReduction>330.625</mechanicalReduction> --> <!-- 529/16 -->
      <mechanicalReduction>333.0</mechanicalReduction>
    </actuator>
  </transmission>

<!-- LADO DERECHO  -->

<!-- MOTOR 2 -->
 <link name="link21">
    <inertial>
      <mass value="1"/>
      <inertia ixx="1" iyy="1" izz="1" ixy="0" ixz="0" iyz="0"/>
    </inertial>
  </link>

  <link name="link22">
    <inertial>
      <mass value="1"/>
      <inertia ixx="1" iyy="1" izz="1" ixy="0" ixz="0" iyz="0"/>
    </inertial>
  </link>

  <joint name="test_joint2" type="revolute">
    <parent link="link21"/>
    <child link="link22"/>
    <limit lower="-10000.0" upper="10000.0" effort="3.0" velocity="10.0">
    ## effort in  (N-m )
    ## velocity in rad/s
    </limit>
  </joint>

  <transmission name="test_joint_trans2">
    <type>transmission_interface/SimpleTransmission</type>
    <joint name="test_joint2">
      <!-- <hardwareInterface>hardware_interface/VelocityJointInterface</hardwareInterface> -->
      <hardwareInterface>hardware_interface/PositionJointInterface</hardwareInterface>
    </joint>
    <actuator name="epos_hardware/right_drive_actuator">
      <!-- <mechanicalReduction>330.625</mechanicalReduction> --> <!-- 529/16 -->
      <mechanicalReduction>333.0</mechanicalReduction>
    </actuator>
  </transmission>


<!-- MOTOR 4 -->
 <link name="link41">
    <inertial>
      <mass value="1"/>
      <inertia ixx="1" iyy="1" izz="1" ixy="0" ixz="0" iyz="0"/>
    </inertial>
  </link>

  <link name="link42">
    <inertial>
      <mass value="1"/>
      <inertia ixx="1" iyy="1" izz="1" ixy="0" ixz="0" iyz="0"/>
    </inertial>
  </link>

  <joint name="test_joint4" type="revolute">
    <parent link="link41"/>
    <child link="link42"/>
    <limit lower="-10000.0" upper="10000.0" effort="3.0" velocity="10.0">
    ## effort in  (N-m )
    ## velocity in rad/s
    </limit>
  </joint>

  <transmission name="test_joint_trans4">
    <type>transmission_interface/SimpleTransmission</type>
    <joint name="test_joint4">
      <!-- <hardwareInterface>hardware_interface/VelocityJointInterface</hardwareInterface> -->
      <hardwareInterface>hardware_interface/PositionJointInterface</hardwareInterface>
    </joint>
    <actuator name="epos_hardware/middle_right_drive_actuator">
      <!-- <mechanicalReduction>330.625</mechanicalReduction> --> <!-- 529/16 -->
      <mechanicalReduction>333.0</mechanicalReduction>
    </actuator>
  </transmission>



<!-- MOTOR 6 -->
 <link name="link61">
    <inertial>
      <mass value="1"/>
      <inertia ixx="1" iyy="1" izz="1" ixy="0" ixz="0" iyz="0"/>
    </inertial>
  </link>

  <link name="link62">
    <inertial>
      <mass value="1"/>
      <inertia ixx="1" iyy="1" izz="1" ixy="0" ixz="0" iyz="0"/>
    </inertial>
  </link>

  <joint name="test_joint6" type="revolute">
    <parent link="link61"/>
    <child link="link62"/>
    <limit lower="-10000.0" upper="10000.0" effort="3.0" velocity="10.0">
    ## effort in  (N-m )
    ## velocity in rad/s
    </limit>
  </joint>

  <transmission name="test_joint_trans6">
    <type>transmission_interface/SimpleTransmission</type>
    <joint name="test_joint6">
      <!-- <hardwareInterface>hardware_interface/VelocityJointInterface</hardwareInterface> -->
      <hardwareInterface>hardware_interface/PositionJointInterface</hardwareInterface>
    </joint>
    <actuator name="epos_hardware/back_right_drive_actuator">
      <!-- <mechanicalReduction>330.625</mechanicalReduction> --> <!-- 529/16 -->
      <mechanicalReduction>333.0</mechanicalReduction>
    </actuator>
  </transmission>

</robot>
