<?xml version="1.0"?>
<robot name="example">

<!-- CHASSIS -->
  <link name="chassis">
    <inertial>
      <origin xyz="${0/1e3} 0 ${1.417/1000}" rpy="${pi/2} 0 ${pi/2}"/>
        <mass value="5.771"/>
        <inertia ixx="${207161.695/(1e6)}"
                 ixy="${0}"                 iyy="${117325.409/(1e6)}"
                 ixz="${0}"                 iyz="${0}"                  izz="${320415.187/(1e6)}"/>
    </inertial>

    <visual>
      <origin xyz="${-300/1e3} 0 0" rpy="${pi/2} 0 ${pi/2}"/>
      <geometry>
        <mesh filename="package://rhex_description/meshes/caja.stl" scale="0.001 0.001 0.001"/>
      </geometry>
      <material name="base_link_material">
        <color rgba="${51/255} ${102/255} ${0/255} 1"/>
      </material>
    </visual>
    <collision>
      <origin xyz="${-300/1e3} 0 0" rpy="${pi/2} 0 ${pi/2}"/>
      <geometry>
        <mesh filename="package://epos_hardware/robot/caja.stl" scale="0.001 0.001 0.001"/>
      </geometry>
    </collision>
  </link>

<!-- LEG 1 -->
<link name="leg_1">
  <inertial>
    <mass value="0.057"/>
    <inertia ixx="${1038.176/(1e6)}"
                         ixy="${-218.169/(1e6)}"     iyy="${273.753/(1e6)}"
                         ixz="${59.956/(1e6)}"       iyz="${153.627/(1e6)}"      izz="${1217.746/(1e6)}"/>
  </inertial>
  <visual>
    <origin xyz="0 0 0" rpy="0 0 0"/>
    <geometry>
      <mesh filename="package://epos_hardware/robot/pvc.stl" scale="0.001 0.001 0.001"/>
    </geometry>
    <material name="Grey">
      <color rgba="0.1 0.1 0.1 1"/>
    </material>
  </visual>

</link>

<!-- LEG 2 -->
<link name="leg_2">
  <inertial>
    <mass value="0.057"/>
    <inertia ixx="${1038.176/(1e6)}"
                         ixy="${-218.169/(1e6)}"     iyy="${273.753/(1e6)}"
                         ixz="${59.956/(1e6)}"       iyz="${153.627/(1e6)}"      izz="${1217.746/(1e6)}"/>
  </inertial>
  <visual>
    <origin xyz="0 0 0" rpy="1.57 0 0"/>
    <geometry>
      <mesh filename="package://epos_hardware/robot/pvc.stl" scale="0.001 0.001 0.001"/>
    </geometry>
    <material name="Grey">
      <color rgba="0.1 0.1 0.1 1"/>
    </material>
  </visual>
</link>

<!-- LEG 3 -->
<link name="leg_3">
<inertial>
  <mass value="0.057"/>
  <inertia ixx="${1038.176/(1e6)}"
                       ixy="${-218.169/(1e6)}"     iyy="${273.753/(1e6)}"
                       ixz="${59.956/(1e6)}"       iyz="${153.627/(1e6)}"      izz="${1217.746/(1e6)}"/>
</inertial>
<visual>
  <origin xyz="0 0 0" rpy="0 0 0"/>
  <geometry>
    <mesh filename="package://epos_hardware/robot/pvc.stl" scale="0.001 0.001 0.001"/>
  </geometry>
  <material name="Grey">
    <color rgba="0.1 0.1 0.1 1"/>
  </material>
</visual>
</link>

<!-- LEG 4 -->
<link name="leg_4">
<inertial>
  <mass value="0.057"/>
  <inertia ixx="${1038.176/(1e6)}"
                       ixy="${-218.169/(1e6)}"     iyy="${273.753/(1e6)}"
                       ixz="${59.956/(1e6)}"       iyz="${153.627/(1e6)}"      izz="${1217.746/(1e6)}"/>
</inertial>
<visual>
  <origin xyz="0 0 0" rpy="1.57 0 0"/>
  <geometry>
    <mesh filename="package://epos_hardware/robot/pvc.stl" scale="0.001 0.001 0.001"/>
  </geometry>
  <material name="Grey">
    <color rgba="0.1 0.1 0.1 1"/>
  </material>
</visual>
</link>

<!-- LEG 5 -->
<link name="leg_5">
<inertial>
  <mass value="0.057"/>
  <inertia ixx="${1038.176/(1e6)}"
                       ixy="${-218.169/(1e6)}"     iyy="${273.753/(1e6)}"
                       ixz="${59.956/(1e6)}"       iyz="${153.627/(1e6)}"      izz="${1217.746/(1e6)}"/>
</inertial>
<visual>
  <origin xyz="0 0 0" rpy="0 0 0"/>
  <geometry>
    <mesh filename="package://epos_hardware/robot/pvc.stl" scale="0.001 0.001 0.001"/>
  </geometry>
  <material name="Grey">
    <color rgba="0.1 0.1 0.1 1"/>
  </material>
</visual>
</link>

<!-- LEG 6 -->
<link name="leg_6">
<inertial>
  <mass value="0.057"/>
  <inertia ixx="${1038.176/(1e6)}"
                       ixy="${-218.169/(1e6)}"     iyy="${273.753/(1e6)}"
                       ixz="${59.956/(1e6)}"       iyz="${153.627/(1e6)}"      izz="${1217.746/(1e6)}"/>
</inertial>
<visual>
  <origin xyz="0 0 0" rpy="1.57 0 0"/>
  <geometry>
    <mesh filename="package://epos_hardware/robot/pvc.stl" scale="0.001 0.001 0.001"/>
  </geometry>
  <material name="Grey">
    <color rgba="0.1 0.1 0.1 1"/>
  </material>
</visual>
</link>
  
<!-- JOINT 1 -->
  <joint name="joint_1" type="revolute">
    <parent link="chassis"/>
    <child link="leg_1"/>
    <!--limit lower="-10000.0" upper="10000.0" effort="3.5" velocity="38.0">
    ## effort in  (N-m )
    ## velocity in rad/s
    </limit-->
  </joint>

  <transmission name="transmission_1">
    <type>transmission_interface/SimpleTransmission</type>
    <joint name="joint_1">
      <hardwareInterface>hardware_interface/VelocityJointInterface</hardwareInterface>
    </joint>
    <actuator name="hexapodo/front_left_drive_actuator">
      <mechanicalReduction>33.0625</mechanicalReduction> <!-- 529/16 -->
    </actuator>
  </transmission>

<!-- JOINT 2 -->
  <joint name="joint_2" type="revolute">
    <parent link="chassis"/>
    <child link="leg_2"/>
    <limit lower="-10000.0" upper="10000.0" effort="3.5" velocity="38.0">
    ## effort in  (N-m )
    ## velocity in rad/s
    </limit>
  </joint>

  <transmission name="transmission_2">
    <type>transmission_interface/SimpleTransmission</type>
    <joint name="joint_2">
      <hardwareInterface>hardware_interface/VelocityJointInterface</hardwareInterface>
    </joint>
    <actuator name="hexapodo/front_right_drive_actuator">
      <mechanicalReduction>33.0625</mechanicalReduction> <!-- 529/16 -->
    </actuator>
  </transmission>


<!-- JOINT 3-->
  <joint name="joint_3" type="revolute">
    <parent link="chassis"/>
    <child link="leg_3"/>
    <limit lower="-10000.0" upper="10000.0" effort="3.5" velocity="38.0">
    ## effort in  (N-m )
    ## velocity in rad/s
    </limit>
  </joint>

  <transmission name="transmission_3">
    <type>transmission_interface/SimpleTransmission</type>
    <joint name="joint_3">
      <hardwareInterface>hardware_interface/VelocityJointInterface</hardwareInterface>
    </joint>
    <actuator name="hexapodo/middle_left_drive_actuator">
      <mechanicalReduction>330.625</mechanicalReduction> <!-- 529/16 -->
    </actuator>
  </transmission>

<!-- JOINT 4 -->
  <joint name="joint_4" type="revolute">
    <parent link="chassis"/>
    <child link="leg_4"/>
    <limit lower="-10000.0" upper="10000.0" effort="3.5" velocity="38.0">
    ## effort in  (N-m )
    ## velocity in rad/s
    </limit>
  </joint>

  <transmission name="transmission_4">
    <type>transmission_interface/SimpleTransmission</type>
    <joint name="joint_4">
      <hardwareInterface>hardware_interface/VelocityJointInterface</hardwareInterface>
    </joint>
    <actuator name="hexapodo/middle_right_drive_actuator">
      <mechanicalReduction>33.0625</mechanicalReduction> <!-- 529/16 -->
    </actuator>
  </transmission>


<!-- JOINT 5 -->
  <joint name="joint_5" type="revolute">
    <parent link="chassis"/>
    <child link="leg_5"/>
    <limit lower="-10000.0" upper="10000.0" effort="3.5" velocity="38.0">
    ## effort in  (N-m )
    ## velocity in rad/s
    </limit>
  </joint>

  <transmission name="transmission_5">
    <type>transmission_interface/SimpleTransmission</type>
    <joint name="joint_5">
      <hardwareInterface>hardware_interface/VelocityJointInterface</hardwareInterface>
    </joint>
    <actuator name="hexapodo/back_left_drive_actuator">
      <mechanicalReduction>33.0625</mechanicalReduction> <!-- 529/16 -->
    </actuator>
  </transmission>


<!-- JOINT 6 -->
  <joint name="joint_6" type="revolute">
    <parent link="chassis"/>
    <child link="leg_6"/>
    <limit lower="-10000.0" upper="10000.0" effort="3.5" velocity="38.0">
    ## effort in  (N-m )
    ## velocity in rad/s
    </limit>
  </joint>

  <transmission name="transmission_6">
    <type>transmission_interface/SimpleTransmission</type>
    <joint name="joint_6">
      <hardwareInterface>hardware_interface/VelocityJointInterface</hardwareInterface>
    </joint>
    <actuator name="hexapodo/back_right_drive_actuator">
      <mechanicalReduction>33.0625</mechanicalReduction> <!-- 529/16 -->
    </actuator>
  </transmission>

</robot>
